INFO:root:Retrieving tapas-comic-page.views as-of Current_as_of 2017-12-27-02-10
INFO:root:Downloading and caching http://tapas.io/series/Camellia as-of 2017-12-27-02-10
INFO:root:Parsing tapas-comic-page.views
INFO:root:Retrieving webtoons.montly_pvs as-of Current_as_of 2017-12-27-02-10
INFO:root:Downloading and caching http://www.webtoons.com/challenge/titleStat?titleNo=81223 as-of 2017-12-27-02-10
INFO:root:Parsing webtoons.montly_pvs
INFO:root:Retrieving webtoons.subs as-of Current_as_of 2017-12-27-02-10
INFO:root:Parsing webtoons.subs
INFO:root:Retrieving webtoons.likes as-of Current_as_of 2017-12-27-02-10
INFO:root:Parsing webtoons.likes
INFO:root:Retrieving tapas-creator-page.subs as-of Current_as_of 2017-12-27-02-10
INFO:root:Downloading and caching https://tapas.io/ladypcpx/subscribers as-of 2017-12-27-02-10
INFO:root:Parsing tapas-creator-page.subs
INFO:root:Appending successful scrapes to event-log: {'2017-12-27-02-10': {'tapas-creator-page.subs': 10375, 'webtoons.subs': 17184, 'webtoons.likes': 29736, 'webtoons.montly_pvs': 116180, 'tapas-comic-page.views': 299350}}
To https://github.com/kshitijl/camellia-stats.git
   2ec431b..46aa75c  master -> master
INFO:root:Retrieving tapas-comic-page.views as-of Current_as_of 2017-12-27-05-42
INFO:root:There was trouble scraping tapas-comic-page.views
INFO:root:Traceback (most recent call last):
  File "./scrape-camellia-stats.py", line 155, in scrape_some
    answer[stat] = self.scrape_one(stat, as_of)
  File "./scrape-camellia-stats.py", line 143, in scrape_one
    content         = page.retrieve_content(as_of)
  File "./scrape-camellia-stats.py", line 101, in retrieve_content
    return self.download_and_save_content(as_of.time)
  File "./scrape-camellia-stats.py", line 88, in download_and_save_content
    content = self.retriever.retrieve()
  File "./scrape-camellia-stats.py", line 214, in retrieve
    return download_with_user_agent(self.url)
  File "./scrape-camellia-stats.py", line 22, in download_with_user_agent
    return requests.get(url,headers=headers).content
  File "/Users/kshitijlauria/Dropbox/src/camellia-stats/virtual-environment/lib/python2.7/site-packages/requests/api.py", line 72, in get
    return request('get', url, params=params, **kwargs)
  File "/Users/kshitijlauria/Dropbox/src/camellia-stats/virtual-environment/lib/python2.7/site-packages/requests/api.py", line 58, in request
    return session.request(method=method, url=url, **kwargs)
  File "/Users/kshitijlauria/Dropbox/src/camellia-stats/virtual-environment/lib/python2.7/site-packages/requests/sessions.py", line 508, in request
    resp = self.send(prep, **send_kwargs)
  File "/Users/kshitijlauria/Dropbox/src/camellia-stats/virtual-environment/lib/python2.7/site-packages/requests/sessions.py", line 618, in send
    r = adapter.send(request, **kwargs)
  File "/Users/kshitijlauria/Dropbox/src/camellia-stats/virtual-environment/lib/python2.7/site-packages/requests/adapters.py", line 508, in send
    raise ConnectionError(e, request=request)
ConnectionError: HTTPConnectionPool(host='tapas.io', port=80): Max retries exceeded with url: /series/Camellia (Caused by NewConnectionError('<urllib3.connection.HTTPConnection object at 0x10ee167d0>: Failed to establish a new connection: [Errno 8] nodename nor servname provided, or not known',))

INFO:root:Retrieving webtoons.montly_pvs as-of Current_as_of 2017-12-27-05-42
INFO:root:There was trouble scraping webtoons.montly_pvs
INFO:root:Traceback (most recent call last):
  File "./scrape-camellia-stats.py", line 155, in scrape_some
    answer[stat] = self.scrape_one(stat, as_of)
  File "./scrape-camellia-stats.py", line 143, in scrape_one
    content         = page.retrieve_content(as_of)
  File "./scrape-camellia-stats.py", line 101, in retrieve_content
    return self.download_and_save_content(as_of.time)
  File "./scrape-camellia-stats.py", line 88, in download_and_save_content
    content = self.retriever.retrieve()
  File "./scrape-camellia-stats.py", line 189, in retrieve
    username_field = browser.find_by_id("emailId")[0]
  File "/Users/kshitijlauria/Dropbox/src/camellia-stats/virtual-environment/lib/python2.7/site-packages/splinter/element_list.py", line 44, in __getitem__
    self.find_by, self.query))
ElementDoesNotExist: no elements could be found with id "emailId"

INFO:root:Retrieving webtoons.subs as-of Current_as_of 2017-12-27-05-42
INFO:root:There was trouble scraping webtoons.subs
INFO:root:Traceback (most recent call last):
  File "./scrape-camellia-stats.py", line 155, in scrape_some
    answer[stat] = self.scrape_one(stat, as_of)
  File "./scrape-camellia-stats.py", line 143, in scrape_one
    content         = page.retrieve_content(as_of)
  File "./scrape-camellia-stats.py", line 101, in retrieve_content
    return self.download_and_save_content(as_of.time)
  File "./scrape-camellia-stats.py", line 88, in download_and_save_content
    content = self.retriever.retrieve()
  File "./scrape-camellia-stats.py", line 189, in retrieve
    username_field = browser.find_by_id("emailId")[0]
  File "/Users/kshitijlauria/Dropbox/src/camellia-stats/virtual-environment/lib/python2.7/site-packages/splinter/element_list.py", line 44, in __getitem__
    self.find_by, self.query))
ElementDoesNotExist: no elements could be found with id "emailId"

INFO:root:Retrieving webtoons.likes as-of Current_as_of 2017-12-27-05-42
INFO:root:There was trouble scraping webtoons.likes
INFO:root:Traceback (most recent call last):
  File "./scrape-camellia-stats.py", line 155, in scrape_some
    answer[stat] = self.scrape_one(stat, as_of)
  File "./scrape-camellia-stats.py", line 143, in scrape_one
    content         = page.retrieve_content(as_of)
  File "./scrape-camellia-stats.py", line 101, in retrieve_content
    return self.download_and_save_content(as_of.time)
  File "./scrape-camellia-stats.py", line 88, in download_and_save_content
    content = self.retriever.retrieve()
  File "./scrape-camellia-stats.py", line 189, in retrieve
    username_field = browser.find_by_id("emailId")[0]
  File "/Users/kshitijlauria/Dropbox/src/camellia-stats/virtual-environment/lib/python2.7/site-packages/splinter/element_list.py", line 44, in __getitem__
    self.find_by, self.query))
ElementDoesNotExist: no elements could be found with id "emailId"

INFO:root:Retrieving tapas-creator-page.subs as-of Current_as_of 2017-12-27-05-42
INFO:root:There was trouble scraping tapas-creator-page.subs
INFO:root:Traceback (most recent call last):
  File "./scrape-camellia-stats.py", line 155, in scrape_some
    answer[stat] = self.scrape_one(stat, as_of)
  File "./scrape-camellia-stats.py", line 143, in scrape_one
    content         = page.retrieve_content(as_of)
  File "./scrape-camellia-stats.py", line 101, in retrieve_content
    return self.download_and_save_content(as_of.time)
  File "./scrape-camellia-stats.py", line 88, in download_and_save_content
    content = self.retriever.retrieve()
  File "./scrape-camellia-stats.py", line 214, in retrieve
    return download_with_user_agent(self.url)
  File "./scrape-camellia-stats.py", line 22, in download_with_user_agent
    return requests.get(url,headers=headers).content
  File "/Users/kshitijlauria/Dropbox/src/camellia-stats/virtual-environment/lib/python2.7/site-packages/requests/api.py", line 72, in get
    return request('get', url, params=params, **kwargs)
  File "/Users/kshitijlauria/Dropbox/src/camellia-stats/virtual-environment/lib/python2.7/site-packages/requests/api.py", line 58, in request
    return session.request(method=method, url=url, **kwargs)
  File "/Users/kshitijlauria/Dropbox/src/camellia-stats/virtual-environment/lib/python2.7/site-packages/requests/sessions.py", line 508, in request
    resp = self.send(prep, **send_kwargs)
  File "/Users/kshitijlauria/Dropbox/src/camellia-stats/virtual-environment/lib/python2.7/site-packages/requests/sessions.py", line 618, in send
    r = adapter.send(request, **kwargs)
  File "/Users/kshitijlauria/Dropbox/src/camellia-stats/virtual-environment/lib/python2.7/site-packages/requests/adapters.py", line 508, in send
    raise ConnectionError(e, request=request)
ConnectionError: HTTPSConnectionPool(host='tapas.io', port=443): Max retries exceeded with url: /ladypcpx/subscribers (Caused by NewConnectionError('<urllib3.connection.VerifiedHTTPSConnection object at 0x10eee52d0>: Failed to establish a new connection: [Errno 8] nodename nor servname provided, or not known',))

INFO:root:Nothing to append to log, exiting
fatal: unable to access 'https://github.com/kshitijl/camellia-stats.git/': Could not resolve host: github.com
INFO:root:Retrieving tapas-comic-page.views as-of Current_as_of 2017-12-27-12-00
INFO:root:Downloading and caching http://tapas.io/series/Camellia as-of 2017-12-27-12-00
INFO:root:Parsing tapas-comic-page.views
INFO:root:Retrieving webtoons.montly_pvs as-of Current_as_of 2017-12-27-12-00
INFO:root:Downloading and caching http://www.webtoons.com/challenge/titleStat?titleNo=81223 as-of 2017-12-27-12-00
INFO:root:Parsing webtoons.montly_pvs
INFO:root:Retrieving webtoons.subs as-of Current_as_of 2017-12-27-12-00
INFO:root:Parsing webtoons.subs
INFO:root:Retrieving webtoons.likes as-of Current_as_of 2017-12-27-12-00
INFO:root:Parsing webtoons.likes
INFO:root:Retrieving tapas-creator-page.subs as-of Current_as_of 2017-12-27-12-00
INFO:root:Downloading and caching https://tapas.io/ladypcpx/subscribers as-of 2017-12-27-12-00
INFO:root:Parsing tapas-creator-page.subs
INFO:root:Appending successful scrapes to event-log: {'2017-12-27-12-00': {'tapas-creator-page.subs': 10382, 'webtoons.subs': 17207, 'webtoons.likes': 29781, 'webtoons.montly_pvs': 116180, 'tapas-comic-page.views': 299609}}
To https://github.com/kshitijl/camellia-stats.git
   694a66d..5a3358b  master -> master
INFO:root:Retrieving tapas-comic-page.views as-of Current_as_of 2017-12-27-13-00
INFO:root:Downloading and caching http://tapas.io/series/Camellia as-of 2017-12-27-13-00
INFO:root:Parsing tapas-comic-page.views
INFO:root:Retrieving webtoons.montly_pvs as-of Current_as_of 2017-12-27-13-00
INFO:root:Downloading and caching http://www.webtoons.com/challenge/titleStat?titleNo=81223 as-of 2017-12-27-13-00
INFO:root:Parsing webtoons.montly_pvs
INFO:root:Retrieving webtoons.subs as-of Current_as_of 2017-12-27-13-00
INFO:root:Parsing webtoons.subs
INFO:root:Retrieving webtoons.likes as-of Current_as_of 2017-12-27-13-00
INFO:root:Parsing webtoons.likes
INFO:root:Retrieving tapas-creator-page.subs as-of Current_as_of 2017-12-27-13-00
INFO:root:Downloading and caching https://tapas.io/ladypcpx/subscribers as-of 2017-12-27-13-00
INFO:root:Parsing tapas-creator-page.subs
INFO:root:Appending successful scrapes to event-log: {'2017-12-27-13-00': {'tapas-creator-page.subs': 10384, 'webtoons.subs': 17209, 'webtoons.likes': 29781, 'webtoons.montly_pvs': 116180, 'tapas-comic-page.views': 299662}}
To https://github.com/kshitijl/camellia-stats.git
   5a3358b..2148d6a  master -> master
INFO:root:Retrieving tapas-comic-page.views as-of Current_as_of 2017-12-27-15-19
INFO:root:There was trouble scraping tapas-comic-page.views
INFO:root:Traceback (most recent call last):
  File "./scrape-camellia-stats.py", line 155, in scrape_some
    answer[stat] = self.scrape_one(stat, as_of)
  File "./scrape-camellia-stats.py", line 143, in scrape_one
    content         = page.retrieve_content(as_of)
  File "./scrape-camellia-stats.py", line 101, in retrieve_content
    return self.download_and_save_content(as_of.time)
  File "./scrape-camellia-stats.py", line 88, in download_and_save_content
    content = self.retriever.retrieve()
  File "./scrape-camellia-stats.py", line 214, in retrieve
    return download_with_user_agent(self.url)
  File "./scrape-camellia-stats.py", line 22, in download_with_user_agent
    return requests.get(url,headers=headers).content
  File "/Users/kshitijlauria/Dropbox/src/camellia-stats/virtual-environment/lib/python2.7/site-packages/requests/api.py", line 72, in get
    return request('get', url, params=params, **kwargs)
  File "/Users/kshitijlauria/Dropbox/src/camellia-stats/virtual-environment/lib/python2.7/site-packages/requests/api.py", line 58, in request
    return session.request(method=method, url=url, **kwargs)
  File "/Users/kshitijlauria/Dropbox/src/camellia-stats/virtual-environment/lib/python2.7/site-packages/requests/sessions.py", line 508, in request
    resp = self.send(prep, **send_kwargs)
  File "/Users/kshitijlauria/Dropbox/src/camellia-stats/virtual-environment/lib/python2.7/site-packages/requests/sessions.py", line 618, in send
    r = adapter.send(request, **kwargs)
  File "/Users/kshitijlauria/Dropbox/src/camellia-stats/virtual-environment/lib/python2.7/site-packages/requests/adapters.py", line 508, in send
    raise ConnectionError(e, request=request)
ConnectionError: HTTPConnectionPool(host='tapas.io', port=80): Max retries exceeded with url: /series/Camellia (Caused by NewConnectionError('<urllib3.connection.HTTPConnection object at 0x10e8507d0>: Failed to establish a new connection: [Errno 8] nodename nor servname provided, or not known',))

INFO:root:Retrieving webtoons.montly_pvs as-of Current_as_of 2017-12-27-15-19
INFO:root:There was trouble scraping webtoons.montly_pvs
INFO:root:Traceback (most recent call last):
  File "./scrape-camellia-stats.py", line 155, in scrape_some
    answer[stat] = self.scrape_one(stat, as_of)
  File "./scrape-camellia-stats.py", line 143, in scrape_one
    content         = page.retrieve_content(as_of)
  File "./scrape-camellia-stats.py", line 101, in retrieve_content
    return self.download_and_save_content(as_of.time)
  File "./scrape-camellia-stats.py", line 88, in download_and_save_content
    content = self.retriever.retrieve()
  File "./scrape-camellia-stats.py", line 189, in retrieve
    username_field = browser.find_by_id("emailId")[0]
  File "/Users/kshitijlauria/Dropbox/src/camellia-stats/virtual-environment/lib/python2.7/site-packages/splinter/element_list.py", line 44, in __getitem__
    self.find_by, self.query))
ElementDoesNotExist: no elements could be found with id "emailId"

INFO:root:Retrieving webtoons.subs as-of Current_as_of 2017-12-27-15-19
INFO:root:There was trouble scraping webtoons.subs
INFO:root:Traceback (most recent call last):
  File "./scrape-camellia-stats.py", line 155, in scrape_some
    answer[stat] = self.scrape_one(stat, as_of)
  File "./scrape-camellia-stats.py", line 143, in scrape_one
    content         = page.retrieve_content(as_of)
  File "./scrape-camellia-stats.py", line 101, in retrieve_content
    return self.download_and_save_content(as_of.time)
  File "./scrape-camellia-stats.py", line 88, in download_and_save_content
    content = self.retriever.retrieve()
  File "./scrape-camellia-stats.py", line 201, in retrieve
    browser.visit(self.url)
  File "/Users/kshitijlauria/Dropbox/src/camellia-stats/virtual-environment/lib/python2.7/site-packages/splinter/driver/webdriver/__init__.py", line 185, in visit
    self.driver.get(url)
  File "/Users/kshitijlauria/Dropbox/src/camellia-stats/virtual-environment/lib/python2.7/site-packages/selenium/webdriver/remote/webdriver.py", line 323, in get
    self.execute(Command.GET, {'url': url})
  File "/Users/kshitijlauria/Dropbox/src/camellia-stats/virtual-environment/lib/python2.7/site-packages/selenium/webdriver/remote/webdriver.py", line 311, in execute
    self.error_handler.check_response(response)
  File "/Users/kshitijlauria/Dropbox/src/camellia-stats/virtual-environment/lib/python2.7/site-packages/selenium/webdriver/remote/errorhandler.py", line 237, in check_response
    raise exception_class(message, screen, stacktrace)
UnexpectedAlertPresentException: Alert Text: None
Message: unexpected alert open: {Alert text : Unknown error has occurred. Please try again in a moment.}
  (Session info: headless chrome=63.0.3239.84)
  (Driver info: chromedriver=2.34.522932 (4140ab217e1ca1bec0c4b4d1b148f3361eb3a03e),platform=Mac OS X 10.10.5 x86_64)


INFO:root:Retrieving webtoons.likes as-of Current_as_of 2017-12-27-15-19
INFO:root:There was trouble scraping webtoons.likes
INFO:root:Traceback (most recent call last):
  File "./scrape-camellia-stats.py", line 155, in scrape_some
    answer[stat] = self.scrape_one(stat, as_of)
  File "./scrape-camellia-stats.py", line 143, in scrape_one
    content         = page.retrieve_content(as_of)
  File "./scrape-camellia-stats.py", line 101, in retrieve_content
    return self.download_and_save_content(as_of.time)
  File "./scrape-camellia-stats.py", line 88, in download_and_save_content
    content = self.retriever.retrieve()
  File "./scrape-camellia-stats.py", line 189, in retrieve
    username_field = browser.find_by_id("emailId")[0]
  File "/Users/kshitijlauria/Dropbox/src/camellia-stats/virtual-environment/lib/python2.7/site-packages/splinter/element_list.py", line 44, in __getitem__
    self.find_by, self.query))
ElementDoesNotExist: no elements could be found with id "emailId"

INFO:root:Retrieving tapas-creator-page.subs as-of Current_as_of 2017-12-27-15-19
INFO:root:There was trouble scraping tapas-creator-page.subs
INFO:root:Traceback (most recent call last):
  File "./scrape-camellia-stats.py", line 155, in scrape_some
    answer[stat] = self.scrape_one(stat, as_of)
  File "./scrape-camellia-stats.py", line 143, in scrape_one
    content         = page.retrieve_content(as_of)
  File "./scrape-camellia-stats.py", line 101, in retrieve_content
    return self.download_and_save_content(as_of.time)
  File "./scrape-camellia-stats.py", line 88, in download_and_save_content
    content = self.retriever.retrieve()
  File "./scrape-camellia-stats.py", line 214, in retrieve
    return download_with_user_agent(self.url)
  File "./scrape-camellia-stats.py", line 22, in download_with_user_agent
    return requests.get(url,headers=headers).content
  File "/Users/kshitijlauria/Dropbox/src/camellia-stats/virtual-environment/lib/python2.7/site-packages/requests/api.py", line 72, in get
    return request('get', url, params=params, **kwargs)
  File "/Users/kshitijlauria/Dropbox/src/camellia-stats/virtual-environment/lib/python2.7/site-packages/requests/api.py", line 58, in request
    return session.request(method=method, url=url, **kwargs)
  File "/Users/kshitijlauria/Dropbox/src/camellia-stats/virtual-environment/lib/python2.7/site-packages/requests/sessions.py", line 508, in request
    resp = self.send(prep, **send_kwargs)
  File "/Users/kshitijlauria/Dropbox/src/camellia-stats/virtual-environment/lib/python2.7/site-packages/requests/sessions.py", line 618, in send
    r = adapter.send(request, **kwargs)
  File "/Users/kshitijlauria/Dropbox/src/camellia-stats/virtual-environment/lib/python2.7/site-packages/requests/adapters.py", line 508, in send
    raise ConnectionError(e, request=request)
ConnectionError: HTTPSConnectionPool(host='tapas.io', port=443): Max retries exceeded with url: /ladypcpx/subscribers (Caused by NewConnectionError('<urllib3.connection.VerifiedHTTPSConnection object at 0x10f4dfd10>: Failed to establish a new connection: [Errno 8] nodename nor servname provided, or not known',))

INFO:root:Nothing to append to log, exiting
fatal: unable to access 'https://github.com/kshitijl/camellia-stats.git/': Could not resolve host: github.com
INFO:root:Retrieving tapas-comic-page.views as-of Current_as_of 2017-12-27-18-21
INFO:root:There was trouble scraping tapas-comic-page.views
INFO:root:Traceback (most recent call last):
  File "./scrape-camellia-stats.py", line 155, in scrape_some
    answer[stat] = self.scrape_one(stat, as_of)
  File "./scrape-camellia-stats.py", line 143, in scrape_one
    content         = page.retrieve_content(as_of)
  File "./scrape-camellia-stats.py", line 101, in retrieve_content
    return self.download_and_save_content(as_of.time)
  File "./scrape-camellia-stats.py", line 88, in download_and_save_content
    content = self.retriever.retrieve()
  File "./scrape-camellia-stats.py", line 214, in retrieve
    return download_with_user_agent(self.url)
  File "./scrape-camellia-stats.py", line 22, in download_with_user_agent
    return requests.get(url,headers=headers).content
  File "/Users/kshitijlauria/Dropbox/src/camellia-stats/virtual-environment/lib/python2.7/site-packages/requests/api.py", line 72, in get
    return request('get', url, params=params, **kwargs)
  File "/Users/kshitijlauria/Dropbox/src/camellia-stats/virtual-environment/lib/python2.7/site-packages/requests/api.py", line 58, in request
    return session.request(method=method, url=url, **kwargs)
  File "/Users/kshitijlauria/Dropbox/src/camellia-stats/virtual-environment/lib/python2.7/site-packages/requests/sessions.py", line 508, in request
    resp = self.send(prep, **send_kwargs)
  File "/Users/kshitijlauria/Dropbox/src/camellia-stats/virtual-environment/lib/python2.7/site-packages/requests/sessions.py", line 618, in send
    r = adapter.send(request, **kwargs)
  File "/Users/kshitijlauria/Dropbox/src/camellia-stats/virtual-environment/lib/python2.7/site-packages/requests/adapters.py", line 508, in send
    raise ConnectionError(e, request=request)
ConnectionError: HTTPConnectionPool(host='tapas.io', port=80): Max retries exceeded with url: /series/Camellia (Caused by NewConnectionError('<urllib3.connection.HTTPConnection object at 0x107ba9550>: Failed to establish a new connection: [Errno 8] nodename nor servname provided, or not known',))

INFO:root:Retrieving webtoons.montly_pvs as-of Current_as_of 2017-12-27-18-21
INFO:root:There was trouble scraping webtoons.montly_pvs
INFO:root:Traceback (most recent call last):
  File "./scrape-camellia-stats.py", line 155, in scrape_some
    answer[stat] = self.scrape_one(stat, as_of)
  File "./scrape-camellia-stats.py", line 143, in scrape_one
    content         = page.retrieve_content(as_of)
  File "./scrape-camellia-stats.py", line 101, in retrieve_content
    return self.download_and_save_content(as_of.time)
  File "./scrape-camellia-stats.py", line 88, in download_and_save_content
    content = self.retriever.retrieve()
  File "./scrape-camellia-stats.py", line 189, in retrieve
    username_field = browser.find_by_id("emailId")[0]
  File "/Users/kshitijlauria/Dropbox/src/camellia-stats/virtual-environment/lib/python2.7/site-packages/splinter/element_list.py", line 44, in __getitem__
    self.find_by, self.query))
ElementDoesNotExist: no elements could be found with id "emailId"

INFO:root:Retrieving webtoons.subs as-of Current_as_of 2017-12-27-18-21
INFO:root:There was trouble scraping webtoons.subs
INFO:root:Traceback (most recent call last):
  File "./scrape-camellia-stats.py", line 155, in scrape_some
    answer[stat] = self.scrape_one(stat, as_of)
  File "./scrape-camellia-stats.py", line 143, in scrape_one
    content         = page.retrieve_content(as_of)
  File "./scrape-camellia-stats.py", line 101, in retrieve_content
    return self.download_and_save_content(as_of.time)
  File "./scrape-camellia-stats.py", line 88, in download_and_save_content
    content = self.retriever.retrieve()
  File "./scrape-camellia-stats.py", line 189, in retrieve
    username_field = browser.find_by_id("emailId")[0]
  File "/Users/kshitijlauria/Dropbox/src/camellia-stats/virtual-environment/lib/python2.7/site-packages/splinter/element_list.py", line 44, in __getitem__
    self.find_by, self.query))
ElementDoesNotExist: no elements could be found with id "emailId"

INFO:root:Retrieving webtoons.likes as-of Current_as_of 2017-12-27-18-21
INFO:root:There was trouble scraping webtoons.likes
INFO:root:Traceback (most recent call last):
  File "./scrape-camellia-stats.py", line 155, in scrape_some
    answer[stat] = self.scrape_one(stat, as_of)
  File "./scrape-camellia-stats.py", line 143, in scrape_one
    content         = page.retrieve_content(as_of)
  File "./scrape-camellia-stats.py", line 101, in retrieve_content
    return self.download_and_save_content(as_of.time)
  File "./scrape-camellia-stats.py", line 88, in download_and_save_content
    content = self.retriever.retrieve()
  File "./scrape-camellia-stats.py", line 189, in retrieve
    username_field = browser.find_by_id("emailId")[0]
  File "/Users/kshitijlauria/Dropbox/src/camellia-stats/virtual-environment/lib/python2.7/site-packages/splinter/element_list.py", line 44, in __getitem__
    self.find_by, self.query))
ElementDoesNotExist: no elements could be found with id "emailId"

INFO:root:Retrieving tapas-creator-page.subs as-of Current_as_of 2017-12-27-18-21
INFO:root:There was trouble scraping tapas-creator-page.subs
INFO:root:Traceback (most recent call last):
  File "./scrape-camellia-stats.py", line 155, in scrape_some
    answer[stat] = self.scrape_one(stat, as_of)
  File "./scrape-camellia-stats.py", line 143, in scrape_one
    content         = page.retrieve_content(as_of)
  File "./scrape-camellia-stats.py", line 101, in retrieve_content
    return self.download_and_save_content(as_of.time)
  File "./scrape-camellia-stats.py", line 88, in download_and_save_content
    content = self.retriever.retrieve()
  File "./scrape-camellia-stats.py", line 214, in retrieve
    return download_with_user_agent(self.url)
  File "./scrape-camellia-stats.py", line 22, in download_with_user_agent
    return requests.get(url,headers=headers).content
  File "/Users/kshitijlauria/Dropbox/src/camellia-stats/virtual-environment/lib/python2.7/site-packages/requests/api.py", line 72, in get
    return request('get', url, params=params, **kwargs)
  File "/Users/kshitijlauria/Dropbox/src/camellia-stats/virtual-environment/lib/python2.7/site-packages/requests/api.py", line 58, in request
    return session.request(method=method, url=url, **kwargs)
  File "/Users/kshitijlauria/Dropbox/src/camellia-stats/virtual-environment/lib/python2.7/site-packages/requests/sessions.py", line 508, in request
    resp = self.send(prep, **send_kwargs)
  File "/Users/kshitijlauria/Dropbox/src/camellia-stats/virtual-environment/lib/python2.7/site-packages/requests/sessions.py", line 618, in send
    r = adapter.send(request, **kwargs)
  File "/Users/kshitijlauria/Dropbox/src/camellia-stats/virtual-environment/lib/python2.7/site-packages/requests/adapters.py", line 508, in send
    raise ConnectionError(e, request=request)
ConnectionError: HTTPSConnectionPool(host='tapas.io', port=443): Max retries exceeded with url: /ladypcpx/subscribers (Caused by NewConnectionError('<urllib3.connection.VerifiedHTTPSConnection object at 0x10881f2d0>: Failed to establish a new connection: [Errno 8] nodename nor servname provided, or not known',))

INFO:root:Nothing to append to log, exiting
fatal: unable to access 'https://github.com/kshitijl/camellia-stats.git/': Could not resolve host: github.com
INFO:root:Retrieving tapas-comic-page.views as-of Current_as_of 2017-12-27-20-00
INFO:root:Downloading and caching http://tapas.io/series/Camellia as-of 2017-12-27-20-00
INFO:root:Parsing tapas-comic-page.views
INFO:root:Retrieving webtoons.montly_pvs as-of Current_as_of 2017-12-27-20-00
INFO:root:Downloading and caching http://www.webtoons.com/challenge/titleStat?titleNo=81223 as-of 2017-12-27-20-00
INFO:root:Parsing webtoons.montly_pvs
INFO:root:Retrieving webtoons.subs as-of Current_as_of 2017-12-27-20-00
INFO:root:Parsing webtoons.subs
INFO:root:Retrieving webtoons.likes as-of Current_as_of 2017-12-27-20-00
INFO:root:Parsing webtoons.likes
INFO:root:Retrieving tapas-creator-page.subs as-of Current_as_of 2017-12-27-20-00
INFO:root:Downloading and caching https://tapas.io/ladypcpx/subscribers as-of 2017-12-27-20-00
INFO:root:Parsing tapas-creator-page.subs
INFO:root:Appending successful scrapes to event-log: {'2017-12-27-20-00': {'tapas-creator-page.subs': 10393, 'webtoons.subs': 17229, 'webtoons.likes': 29826, 'webtoons.montly_pvs': 116180, 'tapas-comic-page.views': 300092}}
To https://github.com/kshitijl/camellia-stats.git
   2148d6a..7c02d83  master -> master
INFO:root:Retrieving tapas-comic-page.views as-of Current_as_of 2017-12-27-21-38
INFO:root:There was trouble scraping tapas-comic-page.views
INFO:root:Traceback (most recent call last):
  File "./scrape-camellia-stats.py", line 155, in scrape_some
    answer[stat] = self.scrape_one(stat, as_of)
  File "./scrape-camellia-stats.py", line 143, in scrape_one
    content         = page.retrieve_content(as_of)
  File "./scrape-camellia-stats.py", line 101, in retrieve_content
    return self.download_and_save_content(as_of.time)
  File "./scrape-camellia-stats.py", line 88, in download_and_save_content
    content = self.retriever.retrieve()
  File "./scrape-camellia-stats.py", line 214, in retrieve
    return download_with_user_agent(self.url)
  File "./scrape-camellia-stats.py", line 22, in download_with_user_agent
    return requests.get(url,headers=headers).content
  File "/Users/kshitijlauria/Dropbox/src/camellia-stats/virtual-environment/lib/python2.7/site-packages/requests/api.py", line 72, in get
    return request('get', url, params=params, **kwargs)
  File "/Users/kshitijlauria/Dropbox/src/camellia-stats/virtual-environment/lib/python2.7/site-packages/requests/api.py", line 58, in request
    return session.request(method=method, url=url, **kwargs)
  File "/Users/kshitijlauria/Dropbox/src/camellia-stats/virtual-environment/lib/python2.7/site-packages/requests/sessions.py", line 508, in request
    resp = self.send(prep, **send_kwargs)
  File "/Users/kshitijlauria/Dropbox/src/camellia-stats/virtual-environment/lib/python2.7/site-packages/requests/sessions.py", line 618, in send
    r = adapter.send(request, **kwargs)
  File "/Users/kshitijlauria/Dropbox/src/camellia-stats/virtual-environment/lib/python2.7/site-packages/requests/adapters.py", line 508, in send
    raise ConnectionError(e, request=request)
ConnectionError: HTTPConnectionPool(host='tapas.io', port=80): Max retries exceeded with url: /series/Camellia (Caused by NewConnectionError('<urllib3.connection.HTTPConnection object at 0x110f697d0>: Failed to establish a new connection: [Errno 8] nodename nor servname provided, or not known',))

INFO:root:Retrieving webtoons.montly_pvs as-of Current_as_of 2017-12-27-21-38
INFO:root:There was trouble scraping webtoons.montly_pvs
INFO:root:Traceback (most recent call last):
  File "./scrape-camellia-stats.py", line 155, in scrape_some
    answer[stat] = self.scrape_one(stat, as_of)
  File "./scrape-camellia-stats.py", line 143, in scrape_one
    content         = page.retrieve_content(as_of)
  File "./scrape-camellia-stats.py", line 101, in retrieve_content
    return self.download_and_save_content(as_of.time)
  File "./scrape-camellia-stats.py", line 88, in download_and_save_content
    content = self.retriever.retrieve()
  File "./scrape-camellia-stats.py", line 189, in retrieve
    username_field = browser.find_by_id("emailId")[0]
  File "/Users/kshitijlauria/Dropbox/src/camellia-stats/virtual-environment/lib/python2.7/site-packages/splinter/element_list.py", line 44, in __getitem__
    self.find_by, self.query))
ElementDoesNotExist: no elements could be found with id "emailId"

INFO:root:Retrieving webtoons.subs as-of Current_as_of 2017-12-27-21-38
INFO:root:There was trouble scraping webtoons.subs
INFO:root:Traceback (most recent call last):
  File "./scrape-camellia-stats.py", line 155, in scrape_some
    answer[stat] = self.scrape_one(stat, as_of)
  File "./scrape-camellia-stats.py", line 143, in scrape_one
    content         = page.retrieve_content(as_of)
  File "./scrape-camellia-stats.py", line 101, in retrieve_content
    return self.download_and_save_content(as_of.time)
  File "./scrape-camellia-stats.py", line 88, in download_and_save_content
    content = self.retriever.retrieve()
  File "./scrape-camellia-stats.py", line 189, in retrieve
    username_field = browser.find_by_id("emailId")[0]
  File "/Users/kshitijlauria/Dropbox/src/camellia-stats/virtual-environment/lib/python2.7/site-packages/splinter/element_list.py", line 44, in __getitem__
    self.find_by, self.query))
ElementDoesNotExist: no elements could be found with id "emailId"

INFO:root:Retrieving webtoons.likes as-of Current_as_of 2017-12-27-21-38
INFO:root:There was trouble scraping webtoons.likes
INFO:root:Traceback (most recent call last):
  File "./scrape-camellia-stats.py", line 155, in scrape_some
    answer[stat] = self.scrape_one(stat, as_of)
  File "./scrape-camellia-stats.py", line 143, in scrape_one
    content         = page.retrieve_content(as_of)
  File "./scrape-camellia-stats.py", line 101, in retrieve_content
    return self.download_and_save_content(as_of.time)
  File "./scrape-camellia-stats.py", line 88, in download_and_save_content
    content = self.retriever.retrieve()
  File "./scrape-camellia-stats.py", line 189, in retrieve
    username_field = browser.find_by_id("emailId")[0]
  File "/Users/kshitijlauria/Dropbox/src/camellia-stats/virtual-environment/lib/python2.7/site-packages/splinter/element_list.py", line 44, in __getitem__
    self.find_by, self.query))
ElementDoesNotExist: no elements could be found with id "emailId"

INFO:root:Retrieving tapas-creator-page.subs as-of Current_as_of 2017-12-27-21-38
INFO:root:There was trouble scraping tapas-creator-page.subs
INFO:root:Traceback (most recent call last):
  File "./scrape-camellia-stats.py", line 155, in scrape_some
    answer[stat] = self.scrape_one(stat, as_of)
  File "./scrape-camellia-stats.py", line 143, in scrape_one
    content         = page.retrieve_content(as_of)
  File "./scrape-camellia-stats.py", line 101, in retrieve_content
    return self.download_and_save_content(as_of.time)
  File "./scrape-camellia-stats.py", line 88, in download_and_save_content
    content = self.retriever.retrieve()
  File "./scrape-camellia-stats.py", line 214, in retrieve
    return download_with_user_agent(self.url)
  File "./scrape-camellia-stats.py", line 22, in download_with_user_agent
    return requests.get(url,headers=headers).content
  File "/Users/kshitijlauria/Dropbox/src/camellia-stats/virtual-environment/lib/python2.7/site-packages/requests/api.py", line 72, in get
    return request('get', url, params=params, **kwargs)
  File "/Users/kshitijlauria/Dropbox/src/camellia-stats/virtual-environment/lib/python2.7/site-packages/requests/api.py", line 58, in request
    return session.request(method=method, url=url, **kwargs)
  File "/Users/kshitijlauria/Dropbox/src/camellia-stats/virtual-environment/lib/python2.7/site-packages/requests/sessions.py", line 508, in request
    resp = self.send(prep, **send_kwargs)
  File "/Users/kshitijlauria/Dropbox/src/camellia-stats/virtual-environment/lib/python2.7/site-packages/requests/sessions.py", line 618, in send
    r = adapter.send(request, **kwargs)
  File "/Users/kshitijlauria/Dropbox/src/camellia-stats/virtual-environment/lib/python2.7/site-packages/requests/adapters.py", line 508, in send
    raise ConnectionError(e, request=request)
ConnectionError: HTTPSConnectionPool(host='tapas.io', port=443): Max retries exceeded with url: /ladypcpx/subscribers (Caused by NewConnectionError('<urllib3.connection.VerifiedHTTPSConnection object at 0x111bcc2d0>: Failed to establish a new connection: [Errno 8] nodename nor servname provided, or not known',))

INFO:root:Nothing to append to log, exiting
fatal: unable to access 'https://github.com/kshitijl/camellia-stats.git/': Could not resolve host: github.com
INFO:root:Retrieving tapas-comic-page.views as-of Current_as_of 2017-12-28-00-41
INFO:root:There was trouble scraping tapas-comic-page.views
INFO:root:Traceback (most recent call last):
  File "./scrape-camellia-stats.py", line 155, in scrape_some
    answer[stat] = self.scrape_one(stat, as_of)
  File "./scrape-camellia-stats.py", line 143, in scrape_one
    content         = page.retrieve_content(as_of)
  File "./scrape-camellia-stats.py", line 101, in retrieve_content
    return self.download_and_save_content(as_of.time)
  File "./scrape-camellia-stats.py", line 88, in download_and_save_content
    content = self.retriever.retrieve()
  File "./scrape-camellia-stats.py", line 214, in retrieve
    return download_with_user_agent(self.url)
  File "./scrape-camellia-stats.py", line 22, in download_with_user_agent
    return requests.get(url,headers=headers).content
  File "/Users/kshitijlauria/Dropbox/src/camellia-stats/virtual-environment/lib/python2.7/site-packages/requests/api.py", line 72, in get
    return request('get', url, params=params, **kwargs)
  File "/Users/kshitijlauria/Dropbox/src/camellia-stats/virtual-environment/lib/python2.7/site-packages/requests/api.py", line 58, in request
    return session.request(method=method, url=url, **kwargs)
  File "/Users/kshitijlauria/Dropbox/src/camellia-stats/virtual-environment/lib/python2.7/site-packages/requests/sessions.py", line 508, in request
    resp = self.send(prep, **send_kwargs)
  File "/Users/kshitijlauria/Dropbox/src/camellia-stats/virtual-environment/lib/python2.7/site-packages/requests/sessions.py", line 618, in send
    r = adapter.send(request, **kwargs)
  File "/Users/kshitijlauria/Dropbox/src/camellia-stats/virtual-environment/lib/python2.7/site-packages/requests/adapters.py", line 508, in send
    raise ConnectionError(e, request=request)
ConnectionError: HTTPConnectionPool(host='tapas.io', port=80): Max retries exceeded with url: /series/Camellia (Caused by NewConnectionError('<urllib3.connection.HTTPConnection object at 0x105b327d0>: Failed to establish a new connection: [Errno 8] nodename nor servname provided, or not known',))

INFO:root:Retrieving webtoons.montly_pvs as-of Current_as_of 2017-12-28-00-41
INFO:root:There was trouble scraping webtoons.montly_pvs
INFO:root:Traceback (most recent call last):
  File "./scrape-camellia-stats.py", line 155, in scrape_some
    answer[stat] = self.scrape_one(stat, as_of)
  File "./scrape-camellia-stats.py", line 143, in scrape_one
    content         = page.retrieve_content(as_of)
  File "./scrape-camellia-stats.py", line 101, in retrieve_content
    return self.download_and_save_content(as_of.time)
  File "./scrape-camellia-stats.py", line 88, in download_and_save_content
    content = self.retriever.retrieve()
  File "./scrape-camellia-stats.py", line 189, in retrieve
    username_field = browser.find_by_id("emailId")[0]
  File "/Users/kshitijlauria/Dropbox/src/camellia-stats/virtual-environment/lib/python2.7/site-packages/splinter/element_list.py", line 44, in __getitem__
    self.find_by, self.query))
ElementDoesNotExist: no elements could be found with id "emailId"

INFO:root:Retrieving webtoons.subs as-of Current_as_of 2017-12-28-00-41
INFO:root:There was trouble scraping webtoons.subs
INFO:root:Traceback (most recent call last):
  File "./scrape-camellia-stats.py", line 155, in scrape_some
    answer[stat] = self.scrape_one(stat, as_of)
  File "./scrape-camellia-stats.py", line 143, in scrape_one
    content         = page.retrieve_content(as_of)
  File "./scrape-camellia-stats.py", line 101, in retrieve_content
    return self.download_and_save_content(as_of.time)
  File "./scrape-camellia-stats.py", line 88, in download_and_save_content
    content = self.retriever.retrieve()
  File "./scrape-camellia-stats.py", line 189, in retrieve
    username_field = browser.find_by_id("emailId")[0]
  File "/Users/kshitijlauria/Dropbox/src/camellia-stats/virtual-environment/lib/python2.7/site-packages/splinter/element_list.py", line 44, in __getitem__
    self.find_by, self.query))
ElementDoesNotExist: no elements could be found with id "emailId"

INFO:root:Retrieving webtoons.likes as-of Current_as_of 2017-12-28-00-41
INFO:root:There was trouble scraping webtoons.likes
INFO:root:Traceback (most recent call last):
  File "./scrape-camellia-stats.py", line 155, in scrape_some
    answer[stat] = self.scrape_one(stat, as_of)
  File "./scrape-camellia-stats.py", line 143, in scrape_one
    content         = page.retrieve_content(as_of)
  File "./scrape-camellia-stats.py", line 101, in retrieve_content
    return self.download_and_save_content(as_of.time)
  File "./scrape-camellia-stats.py", line 88, in download_and_save_content
    content = self.retriever.retrieve()
  File "./scrape-camellia-stats.py", line 189, in retrieve
    username_field = browser.find_by_id("emailId")[0]
  File "/Users/kshitijlauria/Dropbox/src/camellia-stats/virtual-environment/lib/python2.7/site-packages/splinter/element_list.py", line 44, in __getitem__
    self.find_by, self.query))
ElementDoesNotExist: no elements could be found with id "emailId"

INFO:root:Retrieving tapas-creator-page.subs as-of Current_as_of 2017-12-28-00-41
INFO:root:There was trouble scraping tapas-creator-page.subs
INFO:root:Traceback (most recent call last):
  File "./scrape-camellia-stats.py", line 155, in scrape_some
    answer[stat] = self.scrape_one(stat, as_of)
  File "./scrape-camellia-stats.py", line 143, in scrape_one
    content         = page.retrieve_content(as_of)
  File "./scrape-camellia-stats.py", line 101, in retrieve_content
    return self.download_and_save_content(as_of.time)
  File "./scrape-camellia-stats.py", line 88, in download_and_save_content
    content = self.retriever.retrieve()
  File "./scrape-camellia-stats.py", line 214, in retrieve
    return download_with_user_agent(self.url)
  File "./scrape-camellia-stats.py", line 22, in download_with_user_agent
    return requests.get(url,headers=headers).content
  File "/Users/kshitijlauria/Dropbox/src/camellia-stats/virtual-environment/lib/python2.7/site-packages/requests/api.py", line 72, in get
    return request('get', url, params=params, **kwargs)
  File "/Users/kshitijlauria/Dropbox/src/camellia-stats/virtual-environment/lib/python2.7/site-packages/requests/api.py", line 58, in request
    return session.request(method=method, url=url, **kwargs)
  File "/Users/kshitijlauria/Dropbox/src/camellia-stats/virtual-environment/lib/python2.7/site-packages/requests/sessions.py", line 508, in request
    resp = self.send(prep, **send_kwargs)
  File "/Users/kshitijlauria/Dropbox/src/camellia-stats/virtual-environment/lib/python2.7/site-packages/requests/sessions.py", line 618, in send
    r = adapter.send(request, **kwargs)
  File "/Users/kshitijlauria/Dropbox/src/camellia-stats/virtual-environment/lib/python2.7/site-packages/requests/adapters.py", line 508, in send
    raise ConnectionError(e, request=request)
ConnectionError: HTTPSConnectionPool(host='tapas.io', port=443): Max retries exceeded with url: /ladypcpx/subscribers (Caused by NewConnectionError('<urllib3.connection.VerifiedHTTPSConnection object at 0x1067912d0>: Failed to establish a new connection: [Errno 8] nodename nor servname provided, or not known',))

INFO:root:Nothing to append to log, exiting
